"""
Critical Failure Scenario Tests

These tests ensure the GamificationService is bulletproof under all failure conditions.
System failures could lead to:
- Data corruption (user points lost forever)
- Service unavailability (revenue impact)
- User trust destruction (engagement collapse)

ZERO TOLERANCE for system failures in production.
"""

import asyncio
import random
from datetime import datetime, timezone
from typing import Any, Dict, List
from unittest.mock import AsyncMock, Mock, patch

import pytest
import pytest_asyncio

from core.events import EventBus
from core.exceptions import EventBusError
from services.gamification.engines.points_engine import PointsEngine
from services.gamification.interfaces import ActionType, PointsAwardResult
from services.gamification.service import GamificationService


# Define custom exceptions for testing
class DatabaseError(Exception):
    """Database operation error for testing."""

    pass


class ValidationError(Exception):
    """Validation error for testing."""

    pass


class TestDatabaseFailureResilience:
    """Test system resilience to database failures."""

    @pytest_asyncio.fixture
    async def service_with_database_simulation(self):
        """Create service with database failure simulation."""
        event_bus = Mock(spec=EventBus)
        event_bus.subscribe = AsyncMock()
        event_bus.publish = AsyncMock()

        # Simulate various database failure scenarios
        db_client = Mock()
        db_client.begin_transaction = AsyncMock()
        db_client.commit_transaction = AsyncMock()
        db_client.rollback_transaction = AsyncMock()

        return (
            GamificationService(database_client=db_client, event_bus=event_bus),
            db_client,
        )

    @pytest.mark.asyncio
    async def test_database_connection_loss_recovery(
        self, service_with_database_simulation
    ):
        """Test recovery from database connection loss."""
        service, db_client = service_with_database_simulation

        # Simulate connection loss then recovery
        failure_count = 0

        def simulate_connection_loss(*args, **kwargs):
            nonlocal failure_count
            failure_count += 1
            if failure_count <= 3:
                raise DatabaseError("Connection to database lost")
            # After 3 failures, simulate reconnection
            return {"balance": 100, "transaction_id": "tx_recovery"}

        db_client.execute_query = AsyncMock(side_effect=simulate_connection_loss)

        # Operation should eventually succeed with retry
        result = await service.award_points(
            user_id=1001, action_type=ActionType.DAILY_LOGIN, context={}, points=50
        )

        # Should succeed after retries
        assert result.success is True, "Failed to recover from database connection loss"
        assert db_client.execute_query.call_count > 3, "Did not retry enough times"

    @pytest.mark.asyncio
    async def test_database_deadlock_handling(self, service_with_database_simulation):
        """Test handling of database deadlocks with automatic retry."""
        service, db_client = service_with_database_simulation

        deadlock_count = 0

        def simulate_deadlock(*args, **kwargs):
            nonlocal deadlock_count
            deadlock_count += 1
            if deadlock_count <= 2:
                raise DatabaseError("Deadlock detected and rolled back")
            return {"balance": 100, "transaction_id": "tx_deadlock_resolved"}

        db_client.execute_query = AsyncMock(side_effect=simulate_deadlock)

        result = await service.award_points(
            user_id=1002, action_type=ActionType.MESSAGE_SENT, context={}, points=25
        )

        # Should resolve deadlock with retry
        assert result.success is True, "Failed to handle database deadlock"
        assert deadlock_count > 2, "Deadlock not retried properly"

    @pytest.mark.asyncio
    async def test_database_constraint_violation_handling(
        self, service_with_database_simulation
    ):
        """Test handling of database constraint violations."""
        service, db_client = service_with_database_simulation

        # Simulate constraint violation (e.g., negative balance)
        db_client.execute_query = AsyncMock(
            side_effect=DatabaseError("CHECK constraint failed: balance >= 0")
        )

        result = await service.award_points(
            user_id=1003,
            action_type=ActionType.ADMIN_ADJUSTMENT,
            context={"admin_id": 1},
            points=-10000,  # Would make balance negative
        )

        # Should fail gracefully with clear error
        assert result.success is False, "Should have failed on constraint violation"
        assert (
            "constraint" in result.error_message.lower()
        ), "Error message should mention constraint"

        # Should have attempted rollback
        db_client.rollback_transaction.assert_called()

    @pytest.mark.asyncio
    async def test_database_timeout_handling(self, service_with_database_simulation):
        """Test handling of database query timeouts."""
        service, db_client = service_with_database_simulation

        # Simulate query timeout
        db_client.execute_query = AsyncMock(
            side_effect=DatabaseError("Query timeout after 30 seconds")
        )

        result = await service.award_points(
            user_id=1004, action_type=ActionType.TRIVIA_COMPLETED, context={}, points=75
        )

        # Should fail with timeout error
        assert result.success is False
        assert "timeout" in result.error_message.lower()

    @pytest.mark.asyncio
    async def test_partial_database_failure_isolation(
        self, service_with_database_simulation
    ):
        """Test system isolates partial database failures."""
        service, db_client = service_with_database_simulation

        # Simulate failure for specific operations only
        def selective_failure(query, params=None):
            if "leaderboard" in query:
                raise DatabaseError("Leaderboard table temporarily unavailable")
            return {"balance": 100, "transaction_id": "tx_partial"}

        db_client.execute_query = AsyncMock(side_effect=selective_failure)

        # Points operation should succeed even if leaderboard fails
        with patch.object(
            service.leaderboard_engine, "update_user_position"
        ) as mock_leaderboard:
            mock_leaderboard.side_effect = DatabaseError("Leaderboard failure")

            result = await service.award_points(
                user_id=1005,
                action_type=ActionType.COMMUNITY_PARTICIPATION,
                context={},
                points=30,
            )

        # Core points operation should succeed
        assert result.success is True, "Core operation failed due to peripheral failure"


class TestEventBusFailureResilience:
    """Test resilience to Event Bus failures."""

    @pytest_asyncio.fixture
    async def service_with_eventbus_simulation(self):
        """Create service with Event Bus failure simulation."""
        event_bus = Mock(spec=EventBus)
        event_bus.subscribe = AsyncMock()

        # Mock database for core operations
        db_client = Mock()
        db_client.begin_transaction = AsyncMock()
        db_client.commit_transaction = AsyncMock()
        db_client.execute_query = AsyncMock(
            return_value={"balance": 100, "transaction_id": "tx_001"}
        )

        return (
            GamificationService(database_client=db_client, event_bus=event_bus),
            event_bus,
        )

    @pytest.mark.asyncio
    async def test_event_bus_complete_failure_isolation(
        self, service_with_eventbus_simulation
    ):
        """Test core operations continue when Event Bus completely fails."""
        service, event_bus = service_with_eventbus_simulation

        # Simulate complete Event Bus failure
        event_bus.publish = AsyncMock(
            side_effect=EventBusError("Event Bus service unavailable")
        )

        # Core operations should still work
        result = await service.award_points(
            user_id=2001, action_type=ActionType.DAILY_LOGIN, context={}, points=100
        )

        # Should succeed despite Event Bus failure
        assert (
            result.success is True
        ), "Core operation failed due to Event Bus unavailability"

        # Should have attempted to publish but continued
        assert event_bus.publish.call_count > 0, "Did not attempt to publish events"

    @pytest.mark.asyncio
    async def test_event_publishing_retry_with_exponential_backoff(
        self, service_with_eventbus_simulation
    ):
        """Test event publishing retries with exponential backoff."""
        service, event_bus = service_with_eventbus_simulation

        # Track retry attempts and timing
        retry_attempts = []

        def track_retries(*args, **kwargs):
            retry_attempts.append(time.time())
            if len(retry_attempts) <= 3:
                raise EventBusError("Temporary Event Bus failure")
            return AsyncMock()

        event_bus.publish = AsyncMock(side_effect=track_retries)

        import time

        start_time = time.time()

        result = await service.award_points(
            user_id=2002,
            action_type=ActionType.ACHIEVEMENT_UNLOCKED,
            context={"achievement_id": "test"},
            points=200,
        )

        # Should eventually succeed
        assert result.success is True
        assert len(retry_attempts) > 3, "Not enough retry attempts"

        # Should show exponential backoff timing
        if len(retry_attempts) >= 3:
            interval1 = retry_attempts[1] - retry_attempts[0]
            interval2 = retry_attempts[2] - retry_attempts[1]
            assert interval2 > interval1, "No exponential backoff detected"

    @pytest.mark.asyncio
    async def test_event_subscription_failure_recovery(
        self, service_with_eventbus_simulation
    ):
        """Test recovery from Event Bus subscription failures."""
        service, event_bus = service_with_eventbus_simulation

        # Simulate subscription failure then recovery
        subscription_attempts = 0

        def simulate_subscription_failure(pattern, handler):
            nonlocal subscription_attempts
            subscription_attempts += 1
            if subscription_attempts <= 2:
                raise EventBusError("Failed to subscribe to Event Bus")
            return AsyncMock()

        event_bus.subscribe = AsyncMock(side_effect=simulate_subscription_failure)

        # Should eventually succeed in subscribing
        await service.initialize()

        # Should have retried subscription
        assert subscription_attempts > 2, "Did not retry subscription enough"

    @pytest.mark.asyncio
    async def test_event_handling_failure_isolation(
        self, service_with_eventbus_simulation
    ):
        """Test that event handling failures don't crash the service."""
        service, event_bus = service_with_eventbus_simulation

        # Store event handlers
        handlers = {}

        def store_handler(pattern, handler):
            handlers[pattern] = handler
            return AsyncMock()

        event_bus.subscribe = AsyncMock(side_effect=store_handler)
        await service.initialize()

        # Simulate malformed event that causes handler to fail
        from core.events import UserEvent

        malformed_event = UserEvent(
            event_type="user.created",
            user_id="invalid_user_id",  # Wrong type
            timestamp=datetime.now(timezone.utc),
            data=None,  # Missing data
        )

        user_handler = handlers.get("user.*")
        assert user_handler is not None

        # Handler should not crash the service
        try:
            await user_handler(malformed_event)
        except Exception as e:
            # Should log error but not crash
            assert "invalid" in str(e).lower() or "malformed" in str(e).lower()


class TestCascadingFailureResilience:
    """Test resilience to cascading failures across components."""

    @pytest_asyncio.fixture
    async def service_with_multiple_failures(self):
        """Create service for testing multiple simultaneous failures."""
        event_bus = Mock(spec=EventBus)
        event_bus.subscribe = AsyncMock()
        event_bus.publish = AsyncMock()

        db_client = Mock()
        db_client.begin_transaction = AsyncMock()
        db_client.commit_transaction = AsyncMock()
        db_client.rollback_transaction = AsyncMock()
        db_client.execute_query = AsyncMock()

        return (
            GamificationService(database_client=db_client, event_bus=event_bus),
            db_client,
            event_bus,
        )

    @pytest.mark.asyncio
    async def test_database_and_eventbus_simultaneous_failure(
        self, service_with_multiple_failures
    ):
        """Test handling when both database and Event Bus fail simultaneously."""
        service, db_client, event_bus = service_with_multiple_failures

        # Simulate both systems failing
        db_client.execute_query = AsyncMock(
            side_effect=DatabaseError("Database cluster down")
        )
        event_bus.publish = AsyncMock(
            side_effect=EventBusError("Event Bus cluster down")
        )

        result = await service.award_points(
            user_id=3001, action_type=ActionType.DAILY_LOGIN, context={}, points=50
        )

        # Should fail gracefully with clear error
        assert result.success is False
        assert "database" in result.error_message.lower()

        # Should have attempted both operations
        assert db_client.execute_query.call_count > 0
        assert (
            event_bus.publish.call_count >= 0
        )  # Might not reach Event Bus if DB fails first

    @pytest.mark.asyncio
    async def test_partial_component_failure_degradation(
        self, service_with_multiple_failures
    ):
        """Test graceful degradation when some components fail."""
        service, db_client, event_bus = service_with_multiple_failures

        # Core database works, but ancillary services fail
        db_client.execute_query = AsyncMock(
            return_value={"balance": 100, "transaction_id": "tx_degraded"}
        )

        # Mock component failures
        with patch.object(
            service.achievement_engine, "check_achievements"
        ) as mock_achievements:
            mock_achievements.side_effect = Exception("Achievement service down")

            with patch.object(
                service.leaderboard_engine, "update_user_position"
            ) as mock_leaderboard:
                mock_leaderboard.side_effect = Exception("Leaderboard service down")

                result = await service.award_points(
                    user_id=3002,
                    action_type=ActionType.MESSAGE_SENT,
                    context={},
                    points=25,
                )

        # Core operation should succeed with degraded functionality
        assert (
            result.success is True
        ), "Core operation failed due to ancillary service failures"

        # Should have attempted ancillary operations
        mock_achievements.assert_called()
        mock_leaderboard.assert_called()

    @pytest.mark.asyncio
    async def test_memory_pressure_failure_handling(
        self, service_with_multiple_failures
    ):
        """Test handling of memory pressure and resource exhaustion."""
        service, db_client, event_bus = service_with_multiple_failures

        # Simulate memory pressure causing failures
        memory_error_count = 0

        def simulate_memory_pressure(*args, **kwargs):
            nonlocal memory_error_count
            memory_error_count += 1
            if memory_error_count <= 2:
                raise MemoryError("Insufficient memory available")
            return {"balance": 100, "transaction_id": "tx_memory_recovered"}

        db_client.execute_query = AsyncMock(side_effect=simulate_memory_pressure)

        result = await service.award_points(
            user_id=3003,
            action_type=ActionType.TRIVIA_COMPLETED,
            context={},
            points=100,
        )

        # Should handle memory pressure gracefully
        assert result.success is True, "Failed to handle memory pressure"

    @pytest.mark.asyncio
    async def test_high_load_failure_cascade_prevention(
        self, service_with_multiple_failures
    ):
        """Test prevention of failure cascades under high load."""
        service, db_client, event_bus = service_with_multiple_failures

        # Simulate increasing failure rate under load
        operation_count = 0

        def simulate_load_failures(*args, **kwargs):
            nonlocal operation_count
            operation_count += 1
            # Failure rate increases with load
            failure_probability = min(0.7, operation_count / 100)
            if random.random() < failure_probability:
                raise DatabaseError("Database overloaded")
            return {"balance": 100, "transaction_id": f"tx_load_{operation_count}"}

        db_client.execute_query = AsyncMock(side_effect=simulate_load_failures)

        # Simulate high concurrent load
        tasks = []
        for i in range(50):
            task = service.award_points(
                user_id=4000 + i,
                action_type=ActionType.MESSAGE_SENT,
                context={"load_test": True},
                points=10,
            )
            tasks.append(task)

        results = await asyncio.gather(*tasks, return_exceptions=True)

        # Some operations should succeed despite load
        successful_ops = sum(1 for r in results if hasattr(r, "success") and r.success)
        total_ops = len(results)
        success_rate = successful_ops / total_ops

        # Should maintain some level of service
        assert (
            success_rate > 0.3
        ), f"Success rate too low under load: {success_rate:.2%}"


class TestChaosEngineeringScenarios:
    """Chaos engineering tests for extreme failure scenarios."""

    @pytest_asyncio.fixture
    async def chaos_test_service(self):
        """Create service for chaos engineering tests."""
        event_bus = Mock(spec=EventBus)
        event_bus.subscribe = AsyncMock()
        event_bus.publish = AsyncMock()

        db_client = Mock()
        db_client.begin_transaction = AsyncMock()
        db_client.commit_transaction = AsyncMock()
        db_client.rollback_transaction = AsyncMock()
        db_client.execute_query = AsyncMock()

        return (
            GamificationService(database_client=db_client, event_bus=event_bus),
            db_client,
            event_bus,
        )

    @pytest.mark.asyncio
    async def test_random_component_failures(self, chaos_test_service):
        """Test system resilience to random component failures."""
        service, db_client, event_bus = chaos_test_service

        # Randomly fail different components
        def chaos_database(*args, **kwargs):
            if random.random() < 0.3:  # 30% failure rate
                raise DatabaseError("Random database failure")
            return {"balance": 100, "transaction_id": "tx_chaos"}

        def chaos_eventbus(*args, **kwargs):
            if random.random() < 0.2:  # 20% failure rate
                raise EventBusError("Random Event Bus failure")
            return AsyncMock()

        db_client.execute_query = AsyncMock(side_effect=chaos_database)
        event_bus.publish = AsyncMock(side_effect=chaos_eventbus)

        # Run multiple operations with random failures
        results = []
        for i in range(30):
            try:
                result = await service.award_points(
                    user_id=5000 + i,
                    action_type=ActionType.COMMUNITY_PARTICIPATION,
                    context={"chaos_test": True},
                    points=15,
                )
                results.append(result)
            except Exception as e:
                # Some failures are expected in chaos testing
                results.append(e)

        # Should maintain some level of service despite chaos
        successful_ops = sum(1 for r in results if hasattr(r, "success") and r.success)
        assert (
            successful_ops > 10
        ), f"Too few operations succeeded under chaos: {successful_ops}/30"

    @pytest.mark.asyncio
    async def test_network_partition_simulation(self, chaos_test_service):
        """Test behavior during simulated network partitions."""
        service, db_client, event_bus = chaos_test_service

        # Simulate network partition affecting database connectivity
        partition_active = True

        def simulate_partition(*args, **kwargs):
            if partition_active:
                raise DatabaseError("Network partition: database unreachable")
            return {"balance": 100, "transaction_id": "tx_partition_healed"}

        db_client.execute_query = AsyncMock(side_effect=simulate_partition)

        # First operation should fail due to partition
        result1 = await service.award_points(
            user_id=6001, action_type=ActionType.DAILY_LOGIN, context={}, points=50
        )
        assert result1.success is False

        # Heal partition
        partition_active = False

        # Subsequent operation should succeed
        result2 = await service.award_points(
            user_id=6001, action_type=ActionType.MESSAGE_SENT, context={}, points=25
        )
        assert (
            result2.success is True
        ), "Failed to recover after network partition healed"

    @pytest.mark.asyncio
    async def test_extreme_load_with_failures(self, chaos_test_service):
        """Test system behavior under extreme load combined with failures."""
        service, db_client, event_bus = chaos_test_service

        # Simulate extreme load with increasing failure rates
        request_count = 0

        def extreme_load_simulation(*args, **kwargs):
            nonlocal request_count
            request_count += 1

            # Failure rate increases with load
            failure_rate = min(0.8, request_count / 200)
            if random.random() < failure_rate:
                # Various types of failures under load
                failure_types = [
                    DatabaseError("Connection pool exhausted"),
                    DatabaseError("Query timeout under load"),
                    DatabaseError("Database lock timeout"),
                    MemoryError("Out of memory under load"),
                ]
                raise random.choice(failure_types)

            return {"balance": 100, "transaction_id": f"tx_extreme_{request_count}"}

        db_client.execute_query = AsyncMock(side_effect=extreme_load_simulation)

        # Create extreme concurrent load
        tasks = []
        for i in range(100):
            task = service.award_points(
                user_id=7000 + (i % 20),  # 20 users with multiple operations each
                action_type=ActionType.MESSAGE_SENT,
                context={"extreme_load": True, "operation": i},
                points=5,
            )
            tasks.append(task)

        # Execute with timeout to prevent hanging
        try:
            results = await asyncio.wait_for(
                asyncio.gather(*tasks, return_exceptions=True), timeout=30.0
            )
        except asyncio.TimeoutError:
            pytest.fail("System hung under extreme load")

        # Analyze results
        successful_ops = sum(1 for r in results if hasattr(r, "success") and r.success)
        failed_ops = len(results) - successful_ops

        # System should handle some operations even under extreme conditions
        assert (
            successful_ops > 5
        ), f"System completely failed under extreme load: {successful_ops} successes"

        # Should degrade gracefully, not crash
        assert len(results) == 100, "Some operations were lost (system crash suspected)"

        print(
            f"Extreme load test: {successful_ops} successes, {failed_ops} failures out of 100 operations"
        )
